<?xml version="1.0" encoding="utf-8"?><testsuites><testsuite name="pytest" errors="2" failures="0" skipped="0" tests="2" time="31.938" timestamp="2021-09-27T18:09:19.044858" hostname="sim-hankdeMacBook-Pro.local"><testcase classname="pytest" name="internal" time="0.000"><error message="internal error">def worker_internal_error(self, node, formatted_error):
        """
        pytest_internalerror() was called on the worker.
    
        pytest_internalerror() arguments are an excinfo and an excrepr, which can't
        be serialized, so we go with a poor man's solution of raising an exception
        here ourselves using the formatted message.
        """
        self._active_nodes.remove(node)
        try:
&gt;           assert False, formatted_error
E           AssertionError: Traceback (most recent call last):
E               File "/Library/Frameworks/Python.framework/Versions/3.9/lib/python3.9/site-packages/_pytest/main.py", line 269, in wrap_session
E                 session.exitstatus = doit(config, session) or 0
E               File "/Library/Frameworks/Python.framework/Versions/3.9/lib/python3.9/site-packages/_pytest/main.py", line 323, in _main
E                 config.hook.pytest_runtestloop(session=session)
E               File "/Library/Frameworks/Python.framework/Versions/3.9/lib/python3.9/site-packages/pluggy/hooks.py", line 286, in __call__
E                 return self._hookexec(self, self.get_hookimpls(), kwargs)
E               File "/Library/Frameworks/Python.framework/Versions/3.9/lib/python3.9/site-packages/pluggy/manager.py", line 93, in _hookexec
E                 return self._inner_hookexec(hook, methods, kwargs)
E               File "/Library/Frameworks/Python.framework/Versions/3.9/lib/python3.9/site-packages/pluggy/manager.py", line 84, in &lt;lambda&gt;
E                 self._inner_hookexec = lambda hook, methods, kwargs: hook.multicall(
E               File "/Library/Frameworks/Python.framework/Versions/3.9/lib/python3.9/site-packages/pluggy/callers.py", line 208, in _multicall
E                 return outcome.get_result()
E               File "/Library/Frameworks/Python.framework/Versions/3.9/lib/python3.9/site-packages/pluggy/callers.py", line 80, in get_result
E                 raise ex[1].with_traceback(ex[2])
E               File "/Library/Frameworks/Python.framework/Versions/3.9/lib/python3.9/site-packages/pluggy/callers.py", line 187, in _multicall
E                 res = hook_impl.function(*args)
E               File "/Library/Frameworks/Python.framework/Versions/3.9/lib/python3.9/site-packages/xdist/remote.py", line 87, in pytest_runtestloop
E                 self.run_one_test(torun)
E               File "/Library/Frameworks/Python.framework/Versions/3.9/lib/python3.9/site-packages/xdist/remote.py", line 106, in run_one_test
E                 self.config.hook.pytest_runtest_protocol(item=item, nextitem=nextitem)
E               File "/Library/Frameworks/Python.framework/Versions/3.9/lib/python3.9/site-packages/pluggy/hooks.py", line 286, in __call__
E                 return self._hookexec(self, self.get_hookimpls(), kwargs)
E               File "/Library/Frameworks/Python.framework/Versions/3.9/lib/python3.9/site-packages/pluggy/manager.py", line 93, in _hookexec
E                 return self._inner_hookexec(hook, methods, kwargs)
E               File "/Library/Frameworks/Python.framework/Versions/3.9/lib/python3.9/site-packages/pluggy/manager.py", line 84, in &lt;lambda&gt;
E                 self._inner_hookexec = lambda hook, methods, kwargs: hook.multicall(
E               File "/Library/Frameworks/Python.framework/Versions/3.9/lib/python3.9/site-packages/pluggy/callers.py", line 208, in _multicall
E                 return outcome.get_result()
E               File "/Library/Frameworks/Python.framework/Versions/3.9/lib/python3.9/site-packages/pluggy/callers.py", line 80, in get_result
E                 raise ex[1].with_traceback(ex[2])
E               File "/Library/Frameworks/Python.framework/Versions/3.9/lib/python3.9/site-packages/pluggy/callers.py", line 187, in _multicall
E                 res = hook_impl.function(*args)
E               File "/Library/Frameworks/Python.framework/Versions/3.9/lib/python3.9/site-packages/pytest_rerunfailures.py", line 331, in pytest_runtest_protocol
E                 reports = runtestprotocol(item, nextitem=nextitem, log=False)
E               File "/Library/Frameworks/Python.framework/Versions/3.9/lib/python3.9/site-packages/_pytest/runner.py", line 120, in runtestprotocol
E                 rep = call_and_report(item, "setup", log)
E               File "/Library/Frameworks/Python.framework/Versions/3.9/lib/python3.9/site-packages/_pytest/runner.py", line 217, in call_and_report
E                 report: TestReport = hook.pytest_runtest_makereport(item=item, call=call)
E               File "/Library/Frameworks/Python.framework/Versions/3.9/lib/python3.9/site-packages/pluggy/hooks.py", line 286, in __call__
E                 return self._hookexec(self, self.get_hookimpls(), kwargs)
E               File "/Library/Frameworks/Python.framework/Versions/3.9/lib/python3.9/site-packages/pluggy/manager.py", line 93, in _hookexec
E                 return self._inner_hookexec(hook, methods, kwargs)
E               File "/Library/Frameworks/Python.framework/Versions/3.9/lib/python3.9/site-packages/pluggy/manager.py", line 84, in &lt;lambda&gt;
E                 self._inner_hookexec = lambda hook, methods, kwargs: hook.multicall(
E               File "/Library/Frameworks/Python.framework/Versions/3.9/lib/python3.9/site-packages/pluggy/callers.py", line 203, in _multicall
E                 gen.send(outcome)
E               File "/Users/sim-hank/Documents/web_auto/datahub-web-auto/conftest.py", line 71, in pytest_runtest_makereport
E                 capture_screenshots(case_name)
E               File "/Users/sim-hank/Documents/web_auto/datahub-web-auto/conftest.py", line 119, in capture_screenshots
E                 RunConfig.driver.save_screenshot(image_dir)
E               File "/Library/Frameworks/Python.framework/Versions/3.9/lib/python3.9/site-packages/selenium/webdriver/remote/webdriver.py", line 1055, in save_screenshot
E                 return self.get_screenshot_as_file(filename)
E               File "/Library/Frameworks/Python.framework/Versions/3.9/lib/python3.9/site-packages/selenium/webdriver/remote/webdriver.py", line 1032, in get_screenshot_as_file
E                 png = self.get_screenshot_as_png()
E               File "/Library/Frameworks/Python.framework/Versions/3.9/lib/python3.9/site-packages/selenium/webdriver/remote/webdriver.py", line 1064, in get_screenshot_as_png
E                 return base64.b64decode(self.get_screenshot_as_base64().encode('ascii'))
E               File "/Library/Frameworks/Python.framework/Versions/3.9/lib/python3.9/site-packages/selenium/webdriver/remote/webdriver.py", line 1074, in get_screenshot_as_base64
E                 return self.execute(Command.SCREENSHOT)['value']
E               File "/Library/Frameworks/Python.framework/Versions/3.9/lib/python3.9/site-packages/selenium/webdriver/remote/webdriver.py", line 321, in execute
E                 self.error_handler.check_response(response)
E               File "/Library/Frameworks/Python.framework/Versions/3.9/lib/python3.9/site-packages/selenium/webdriver/remote/errorhandler.py", line 242, in check_response
E                 raise exception_class(message, screen, stacktrace)
E             selenium.common.exceptions.NoSuchWindowException: Message: no such window: window was already closed
E               (Session info: chrome=94.0.4606.61)
E           assert False

/Library/Frameworks/Python.framework/Versions/3.9/lib/python3.9/site-packages/xdist/dsession.py:187: AssertionError</error><error message="internal error">Traceback (most recent call last):
  File "/Library/Frameworks/Python.framework/Versions/3.9/lib/python3.9/site-packages/_pytest/main.py", line 269, in wrap_session
    session.exitstatus = doit(config, session) or 0
  File "/Library/Frameworks/Python.framework/Versions/3.9/lib/python3.9/site-packages/_pytest/main.py", line 323, in _main
    config.hook.pytest_runtestloop(session=session)
  File "/Library/Frameworks/Python.framework/Versions/3.9/lib/python3.9/site-packages/pluggy/hooks.py", line 286, in __call__
    return self._hookexec(self, self.get_hookimpls(), kwargs)
  File "/Library/Frameworks/Python.framework/Versions/3.9/lib/python3.9/site-packages/pluggy/manager.py", line 93, in _hookexec
    return self._inner_hookexec(hook, methods, kwargs)
  File "/Library/Frameworks/Python.framework/Versions/3.9/lib/python3.9/site-packages/pluggy/manager.py", line 84, in &lt;lambda&gt;
    self._inner_hookexec = lambda hook, methods, kwargs: hook.multicall(
  File "/Library/Frameworks/Python.framework/Versions/3.9/lib/python3.9/site-packages/pluggy/callers.py", line 208, in _multicall
    return outcome.get_result()
  File "/Library/Frameworks/Python.framework/Versions/3.9/lib/python3.9/site-packages/pluggy/callers.py", line 80, in get_result
    raise ex[1].with_traceback(ex[2])
  File "/Library/Frameworks/Python.framework/Versions/3.9/lib/python3.9/site-packages/pluggy/callers.py", line 187, in _multicall
    res = hook_impl.function(*args)
  File "/Library/Frameworks/Python.framework/Versions/3.9/lib/python3.9/site-packages/xdist/dsession.py", line 112, in pytest_runtestloop
    self.loop_once()
  File "/Library/Frameworks/Python.framework/Versions/3.9/lib/python3.9/site-packages/xdist/dsession.py", line 135, in loop_once
    call(**kwargs)
  File "/Library/Frameworks/Python.framework/Versions/3.9/lib/python3.9/site-packages/xdist/dsession.py", line 174, in worker_workerfinished
    assert not crashitem, (crashitem, node)
AssertionError: ('test_case/test_001_res_editor_case.py::TestResEditorCase::test_add[oracle]', &lt;WorkerController gw1&gt;)
assert not 'test_case/test_001_res_editor_case.py::TestResEditorCase::test_add[oracle]'</error></testcase></testsuite></testsuites>