<?xml version="1.0" encoding="utf-8"?><testsuites><testsuite name="pytest" errors="2" failures="0" skipped="0" tests="2" time="26.350" timestamp="2021-09-27T18:10:14.142677" hostname="sim-hankdeMacBook-Pro.local"><testcase classname="pytest" name="internal" time="0.000"><error message="internal error">def worker_internal_error(self, node, formatted_error):
        """
        pytest_internalerror() was called on the worker.
    
        pytest_internalerror() arguments are an excinfo and an excrepr, which can't
        be serialized, so we go with a poor man's solution of raising an exception
        here ourselves using the formatted message.
        """
        self._active_nodes.remove(node)
        try:
&gt;           assert False, formatted_error
E           AssertionError: Traceback (most recent call last):
E               File "/Library/Frameworks/Python.framework/Versions/3.9/lib/python3.9/site-packages/execnet/gateway_base.py", line 1400, in _save
E                 dispatch = self._dispatch[tp]
E             KeyError: &lt;class 'py._xmlgen.html'&gt;
E             
E             During handling of the above exception, another exception occurred:
E             
E             Traceback (most recent call last):
E               File "/Library/Frameworks/Python.framework/Versions/3.9/lib/python3.9/site-packages/_pytest/main.py", line 269, in wrap_session
E                 session.exitstatus = doit(config, session) or 0
E               File "/Library/Frameworks/Python.framework/Versions/3.9/lib/python3.9/site-packages/_pytest/main.py", line 323, in _main
E                 config.hook.pytest_runtestloop(session=session)
E               File "/Library/Frameworks/Python.framework/Versions/3.9/lib/python3.9/site-packages/pluggy/hooks.py", line 286, in __call__
E                 return self._hookexec(self, self.get_hookimpls(), kwargs)
E               File "/Library/Frameworks/Python.framework/Versions/3.9/lib/python3.9/site-packages/pluggy/manager.py", line 93, in _hookexec
E                 return self._inner_hookexec(hook, methods, kwargs)
E               File "/Library/Frameworks/Python.framework/Versions/3.9/lib/python3.9/site-packages/pluggy/manager.py", line 84, in &lt;lambda&gt;
E                 self._inner_hookexec = lambda hook, methods, kwargs: hook.multicall(
E               File "/Library/Frameworks/Python.framework/Versions/3.9/lib/python3.9/site-packages/pluggy/callers.py", line 208, in _multicall
E                 return outcome.get_result()
E               File "/Library/Frameworks/Python.framework/Versions/3.9/lib/python3.9/site-packages/pluggy/callers.py", line 80, in get_result
E                 raise ex[1].with_traceback(ex[2])
E               File "/Library/Frameworks/Python.framework/Versions/3.9/lib/python3.9/site-packages/pluggy/callers.py", line 187, in _multicall
E                 res = hook_impl.function(*args)
E               File "/Library/Frameworks/Python.framework/Versions/3.9/lib/python3.9/site-packages/xdist/remote.py", line 87, in pytest_runtestloop
E                 self.run_one_test(torun)
E               File "/Library/Frameworks/Python.framework/Versions/3.9/lib/python3.9/site-packages/xdist/remote.py", line 106, in run_one_test
E                 self.config.hook.pytest_runtest_protocol(item=item, nextitem=nextitem)
E               File "/Library/Frameworks/Python.framework/Versions/3.9/lib/python3.9/site-packages/pluggy/hooks.py", line 286, in __call__
E                 return self._hookexec(self, self.get_hookimpls(), kwargs)
E               File "/Library/Frameworks/Python.framework/Versions/3.9/lib/python3.9/site-packages/pluggy/manager.py", line 93, in _hookexec
E                 return self._inner_hookexec(hook, methods, kwargs)
E               File "/Library/Frameworks/Python.framework/Versions/3.9/lib/python3.9/site-packages/pluggy/manager.py", line 84, in &lt;lambda&gt;
E                 self._inner_hookexec = lambda hook, methods, kwargs: hook.multicall(
E               File "/Library/Frameworks/Python.framework/Versions/3.9/lib/python3.9/site-packages/pluggy/callers.py", line 208, in _multicall
E                 return outcome.get_result()
E               File "/Library/Frameworks/Python.framework/Versions/3.9/lib/python3.9/site-packages/pluggy/callers.py", line 80, in get_result
E                 raise ex[1].with_traceback(ex[2])
E               File "/Library/Frameworks/Python.framework/Versions/3.9/lib/python3.9/site-packages/pluggy/callers.py", line 187, in _multicall
E                 res = hook_impl.function(*args)
E               File "/Library/Frameworks/Python.framework/Versions/3.9/lib/python3.9/site-packages/pytest_rerunfailures.py", line 337, in pytest_runtest_protocol
E                 item.ihook.pytest_runtest_logreport(report=report)
E               File "/Library/Frameworks/Python.framework/Versions/3.9/lib/python3.9/site-packages/pluggy/hooks.py", line 286, in __call__
E                 return self._hookexec(self, self.get_hookimpls(), kwargs)
E               File "/Library/Frameworks/Python.framework/Versions/3.9/lib/python3.9/site-packages/pluggy/manager.py", line 93, in _hookexec
E                 return self._inner_hookexec(hook, methods, kwargs)
E               File "/Library/Frameworks/Python.framework/Versions/3.9/lib/python3.9/site-packages/pluggy/manager.py", line 84, in &lt;lambda&gt;
E                 self._inner_hookexec = lambda hook, methods, kwargs: hook.multicall(
E               File "/Library/Frameworks/Python.framework/Versions/3.9/lib/python3.9/site-packages/pluggy/callers.py", line 208, in _multicall
E                 return outcome.get_result()
E               File "/Library/Frameworks/Python.framework/Versions/3.9/lib/python3.9/site-packages/pluggy/callers.py", line 80, in get_result
E                 raise ex[1].with_traceback(ex[2])
E               File "/Library/Frameworks/Python.framework/Versions/3.9/lib/python3.9/site-packages/pluggy/callers.py", line 187, in _multicall
E                 res = hook_impl.function(*args)
E               File "/Library/Frameworks/Python.framework/Versions/3.9/lib/python3.9/site-packages/xdist/remote.py", line 141, in pytest_runtest_logreport
E                 self.sendevent("testreport", data=data)
E               File "/Library/Frameworks/Python.framework/Versions/3.9/lib/python3.9/site-packages/xdist/remote.py", line 48, in sendevent
E                 self.channel.send((name, kwargs))
E               File "/Library/Frameworks/Python.framework/Versions/3.9/lib/python3.9/site-packages/execnet/gateway_base.py", line 729, in send
E                 self.gateway._send(Message.CHANNEL_DATA, self.id, dumps_internal(item))
E               File "/Library/Frameworks/Python.framework/Versions/3.9/lib/python3.9/site-packages/execnet/gateway_base.py", line 1371, in dumps_internal
E                 return _Serializer().save(obj)
E               File "/Library/Frameworks/Python.framework/Versions/3.9/lib/python3.9/site-packages/execnet/gateway_base.py", line 1389, in save
E                 self._save(obj)
E               File "/Library/Frameworks/Python.framework/Versions/3.9/lib/python3.9/site-packages/execnet/gateway_base.py", line 1407, in _save
E                 dispatch(self, obj)
E               File "/Library/Frameworks/Python.framework/Versions/3.9/lib/python3.9/site-packages/execnet/gateway_base.py", line 1494, in save_tuple
E                 self._save(item)
E               File "/Library/Frameworks/Python.framework/Versions/3.9/lib/python3.9/site-packages/execnet/gateway_base.py", line 1407, in _save
E                 dispatch(self, obj)
E               File "/Library/Frameworks/Python.framework/Versions/3.9/lib/python3.9/site-packages/execnet/gateway_base.py", line 1490, in save_dict
E                 self._write_setitem(key, value)
E               File "/Library/Frameworks/Python.framework/Versions/3.9/lib/python3.9/site-packages/execnet/gateway_base.py", line 1484, in _write_setitem
E                 self._save(value)
E               File "/Library/Frameworks/Python.framework/Versions/3.9/lib/python3.9/site-packages/execnet/gateway_base.py", line 1407, in _save
E                 dispatch(self, obj)
E               File "/Library/Frameworks/Python.framework/Versions/3.9/lib/python3.9/site-packages/execnet/gateway_base.py", line 1490, in save_dict
E                 self._write_setitem(key, value)
E               File "/Library/Frameworks/Python.framework/Versions/3.9/lib/python3.9/site-packages/execnet/gateway_base.py", line 1484, in _write_setitem
E                 self._save(value)
E               File "/Library/Frameworks/Python.framework/Versions/3.9/lib/python3.9/site-packages/execnet/gateway_base.py", line 1405, in _save
E                 raise DumpError("can't serialize {}".format(tp))
E             execnet.gateway_base.DumpError: can't serialize &lt;class 'py._xmlgen.html'&gt;
E           assert False

/Library/Frameworks/Python.framework/Versions/3.9/lib/python3.9/site-packages/xdist/dsession.py:187: AssertionError</error><error message="internal error">Traceback (most recent call last):
  File "/Library/Frameworks/Python.framework/Versions/3.9/lib/python3.9/site-packages/_pytest/main.py", line 269, in wrap_session
    session.exitstatus = doit(config, session) or 0
  File "/Library/Frameworks/Python.framework/Versions/3.9/lib/python3.9/site-packages/_pytest/main.py", line 323, in _main
    config.hook.pytest_runtestloop(session=session)
  File "/Library/Frameworks/Python.framework/Versions/3.9/lib/python3.9/site-packages/pluggy/hooks.py", line 286, in __call__
    return self._hookexec(self, self.get_hookimpls(), kwargs)
  File "/Library/Frameworks/Python.framework/Versions/3.9/lib/python3.9/site-packages/pluggy/manager.py", line 93, in _hookexec
    return self._inner_hookexec(hook, methods, kwargs)
  File "/Library/Frameworks/Python.framework/Versions/3.9/lib/python3.9/site-packages/pluggy/manager.py", line 84, in &lt;lambda&gt;
    self._inner_hookexec = lambda hook, methods, kwargs: hook.multicall(
  File "/Library/Frameworks/Python.framework/Versions/3.9/lib/python3.9/site-packages/pluggy/callers.py", line 208, in _multicall
    return outcome.get_result()
  File "/Library/Frameworks/Python.framework/Versions/3.9/lib/python3.9/site-packages/pluggy/callers.py", line 80, in get_result
    raise ex[1].with_traceback(ex[2])
  File "/Library/Frameworks/Python.framework/Versions/3.9/lib/python3.9/site-packages/pluggy/callers.py", line 187, in _multicall
    res = hook_impl.function(*args)
  File "/Library/Frameworks/Python.framework/Versions/3.9/lib/python3.9/site-packages/xdist/dsession.py", line 112, in pytest_runtestloop
    self.loop_once()
  File "/Library/Frameworks/Python.framework/Versions/3.9/lib/python3.9/site-packages/xdist/dsession.py", line 135, in loop_once
    call(**kwargs)
  File "/Library/Frameworks/Python.framework/Versions/3.9/lib/python3.9/site-packages/xdist/dsession.py", line 174, in worker_workerfinished
    assert not crashitem, (crashitem, node)
AssertionError: ('test_case/test_001_res_editor_case.py::TestResEditorCase::test_add[mysql]', &lt;WorkerController gw0&gt;)
assert not 'test_case/test_001_res_editor_case.py::TestResEditorCase::test_add[mysql]'</error></testcase></testsuite></testsuites>