<?xml version="1.0" encoding="utf-8"?><testsuites><testsuite name="pytest" errors="1" failures="0" skipped="0" tests="4" time="70.662" timestamp="2021-08-02T18:48:48.439578" hostname="sim-hankdeMacBook-Pro.local"><testcase classname="test_case.test_001_res_editor_case.TestResEditorCase" name="test_add[mysql]" time="18.947" /><testcase classname="test_case.test_001_res_editor_case.TestResEditorCase" name="test_add[oracle]" time="16.599" /><testcase classname="test_case.test_001_res_editor_case.TestResEditorCase" name="test_add[sqlserver]" time="15.413" /><testcase time="0.000" /><testcase classname="pytest" name="internal" time="0.000"><error message="internal error">Traceback (most recent call last):
  File "/Library/Frameworks/Python.framework/Versions/3.9/lib/python3.9/site-packages/_pytest/main.py", line 269, in wrap_session
    session.exitstatus = doit(config, session) or 0
  File "/Library/Frameworks/Python.framework/Versions/3.9/lib/python3.9/site-packages/_pytest/main.py", line 323, in _main
    config.hook.pytest_runtestloop(session=session)
  File "/Library/Frameworks/Python.framework/Versions/3.9/lib/python3.9/site-packages/pluggy/hooks.py", line 286, in __call__
    return self._hookexec(self, self.get_hookimpls(), kwargs)
  File "/Library/Frameworks/Python.framework/Versions/3.9/lib/python3.9/site-packages/pluggy/manager.py", line 93, in _hookexec
    return self._inner_hookexec(hook, methods, kwargs)
  File "/Library/Frameworks/Python.framework/Versions/3.9/lib/python3.9/site-packages/pluggy/manager.py", line 84, in &lt;lambda&gt;
    self._inner_hookexec = lambda hook, methods, kwargs: hook.multicall(
  File "/Library/Frameworks/Python.framework/Versions/3.9/lib/python3.9/site-packages/pluggy/callers.py", line 208, in _multicall
    return outcome.get_result()
  File "/Library/Frameworks/Python.framework/Versions/3.9/lib/python3.9/site-packages/pluggy/callers.py", line 80, in get_result
    raise ex[1].with_traceback(ex[2])
  File "/Library/Frameworks/Python.framework/Versions/3.9/lib/python3.9/site-packages/pluggy/callers.py", line 187, in _multicall
    res = hook_impl.function(*args)
  File "/Library/Frameworks/Python.framework/Versions/3.9/lib/python3.9/site-packages/_pytest/main.py", line 348, in pytest_runtestloop
    item.config.hook.pytest_runtest_protocol(item=item, nextitem=nextitem)
  File "/Library/Frameworks/Python.framework/Versions/3.9/lib/python3.9/site-packages/pluggy/hooks.py", line 286, in __call__
    return self._hookexec(self, self.get_hookimpls(), kwargs)
  File "/Library/Frameworks/Python.framework/Versions/3.9/lib/python3.9/site-packages/pluggy/manager.py", line 93, in _hookexec
    return self._inner_hookexec(hook, methods, kwargs)
  File "/Library/Frameworks/Python.framework/Versions/3.9/lib/python3.9/site-packages/pluggy/manager.py", line 84, in &lt;lambda&gt;
    self._inner_hookexec = lambda hook, methods, kwargs: hook.multicall(
  File "/Library/Frameworks/Python.framework/Versions/3.9/lib/python3.9/site-packages/pluggy/callers.py", line 208, in _multicall
    return outcome.get_result()
  File "/Library/Frameworks/Python.framework/Versions/3.9/lib/python3.9/site-packages/pluggy/callers.py", line 80, in get_result
    raise ex[1].with_traceback(ex[2])
  File "/Library/Frameworks/Python.framework/Versions/3.9/lib/python3.9/site-packages/pluggy/callers.py", line 187, in _multicall
    res = hook_impl.function(*args)
  File "/Library/Frameworks/Python.framework/Versions/3.9/lib/python3.9/site-packages/_pytest/runner.py", line 109, in pytest_runtest_protocol
    runtestprotocol(item, nextitem=nextitem)
  File "/Library/Frameworks/Python.framework/Versions/3.9/lib/python3.9/site-packages/_pytest/runner.py", line 126, in runtestprotocol
    reports.append(call_and_report(item, "call", log))
  File "/Library/Frameworks/Python.framework/Versions/3.9/lib/python3.9/site-packages/_pytest/runner.py", line 217, in call_and_report
    report: TestReport = hook.pytest_runtest_makereport(item=item, call=call)
  File "/Library/Frameworks/Python.framework/Versions/3.9/lib/python3.9/site-packages/pluggy/hooks.py", line 286, in __call__
    return self._hookexec(self, self.get_hookimpls(), kwargs)
  File "/Library/Frameworks/Python.framework/Versions/3.9/lib/python3.9/site-packages/pluggy/manager.py", line 93, in _hookexec
    return self._inner_hookexec(hook, methods, kwargs)
  File "/Library/Frameworks/Python.framework/Versions/3.9/lib/python3.9/site-packages/pluggy/manager.py", line 84, in &lt;lambda&gt;
    self._inner_hookexec = lambda hook, methods, kwargs: hook.multicall(
  File "/Library/Frameworks/Python.framework/Versions/3.9/lib/python3.9/site-packages/pluggy/callers.py", line 203, in _multicall
    gen.send(outcome)
  File "/Users/sim-hank/Documents/autotest/ui-auto/datahub_independentV1.0_ui/conftest.py", line 58, in pytest_runtest_makereport
    capture_screenshots(case_name)
  File "/Users/sim-hank/Documents/autotest/ui-auto/datahub_independentV1.0_ui/conftest.py", line 109, in capture_screenshots
    RunConfig.driver.save_screenshot(image_dir)
  File "/Library/Frameworks/Python.framework/Versions/3.9/lib/python3.9/site-packages/selenium/webdriver/remote/webdriver.py", line 1055, in save_screenshot
    return self.get_screenshot_as_file(filename)
  File "/Library/Frameworks/Python.framework/Versions/3.9/lib/python3.9/site-packages/selenium/webdriver/remote/webdriver.py", line 1032, in get_screenshot_as_file
    png = self.get_screenshot_as_png()
  File "/Library/Frameworks/Python.framework/Versions/3.9/lib/python3.9/site-packages/selenium/webdriver/remote/webdriver.py", line 1064, in get_screenshot_as_png
    return base64.b64decode(self.get_screenshot_as_base64().encode('ascii'))
  File "/Library/Frameworks/Python.framework/Versions/3.9/lib/python3.9/site-packages/selenium/webdriver/remote/webdriver.py", line 1074, in get_screenshot_as_base64
    return self.execute(Command.SCREENSHOT)['value']
  File "/Library/Frameworks/Python.framework/Versions/3.9/lib/python3.9/site-packages/selenium/webdriver/remote/webdriver.py", line 321, in execute
    self.error_handler.check_response(response)
  File "/Library/Frameworks/Python.framework/Versions/3.9/lib/python3.9/site-packages/selenium/webdriver/remote/errorhandler.py", line 242, in check_response
    raise exception_class(message, screen, stacktrace)
selenium.common.exceptions.NoSuchWindowException: Message: no such window: window was already closed
  (Session info: chrome=92.0.4515.107)</error></testcase></testsuite></testsuites>